Workbook
Name ClearOldRecord: '13'!ClearOldRecord
Name ClearOldRecord: 'CFT '!ClearOldRecord
Name ClearOldRecord: [1]!ClearOldRecord
Name Entry: '13'!Entry
Name Entry: 'CFT '!Entry
Name Entry: [1]!Entry
Name ExitProgram: '13'!ExitProgram
Name ExitProgram: 'CFT '!ExitProgram
Name ExitProgram: [1]!ExitProgram
Name HistogramWizard: '13'!HistogramWizard
Name HistogramWizard: 'CFT '!HistogramWizard
Name HistogramWizard: [1]!HistogramWizard
Name kk: '13'!kk
Name kk: 'CFT '!kk
Name kk: [1]!kk
Name print: '13'!print
Name print: 'CFT '!print
Name print: [1]!print
Name PrintReport: '13'!PrintReport
Name PrintReport: 'CFT '!PrintReport
Name PrintReport: [1]!PrintReport
Name qwe: '13'!qwe
Name qwe: 'CFT '!qwe
Name qwe: [1]!qwe
Name Retrieve: '13'!Retrieve
Name Retrieve: 'CFT '!Retrieve
Name Retrieve: [1]!Retrieve
Name ReturnTOMain: '13'!ReturnTOMain
Name ReturnTOMain: 'CFT '!ReturnTOMain
Name ReturnTOMain: [1]!ReturnTOMain
Name Save: '13'!Save
Name Save: 'CFT '!Save
Name Save: [1]!Save

Sheet Portada 
B1: Información del Proyecto / Project Information | D1: Rev: 00
A5: Nombre del proyecto / Project name: | B5: Dahlia Valve Stellantis | C5: Inicia / Start: | D5: 45609
A6: Número de parte / Part number: | B6: 1722-EJB0033 | C6: Termina / End: | D6: 47392
A7: Cliente / Customer: | B7: Stellantis | C7: Fecha de PPAP / PPAP Date: | D7: 45524
A8: Aplicación / Application: | B8: AS | C8: Fecha de SOP / SOP Date: | D8: 45609
A9: Línea / Line: | B9: Dahlia Valve | C9: Fecha de término de safe launch / Safe launch finish date: | D9: =IF(D8=0, "",D8+90) -> 45699
A10: Producto / Product: | B10: Dahlia Valve | C10: Administrador de programa / Program Manager:
A11: Razón de la Revisión / Revision Reason: | B11: Nuevo proyecto
A14: Líder del proyecto / Project leader | B14: Mohamed Niaz
A15: Ingeniero de Proyectos / Project Engineer | B15: Eduardo Tejeida
A16: Ingeniero de Calidad / QE | B16: Gabriel Romero
A17: Process Engineer / PE | B17: Jesus Urena
A18: Observaciones / Remarks:

Sheet CFT 
B2: #VALUE! | C2: Cross Functional Team
B6: Customer: | C6: Stellantis | F6: Project BU: | G6: 46
B7: Project name: | C7: Dahlia Valve HD (68591739AA - 1722-EJB0033) | F7: Line: | G7: Dahlia
B8: Plant: | C8: 1 | G8: =IF('[2]Portada '!B10="", "",'[2]Portada '!$B$9)
B10: Manufacturing site | F10: Transfering site
D11: Email | G11: Name | H11: Email
B12: Project leader: | C12: Mohamed Niaz | D12: mohammed.niaz@johnsonelectric.com | F12: Program Manager: | G12: Jit Deodhar | H12: jit.deodhar@johnsonelectric.com
B13: Project Engineer: | C13: Eduardo Tejeida | D13: eduardo.tejeida@johnsonelectric.com | F13: Design Engineer: | G13: Alessandro Bossi | H13: alessandro.florian.bossi@johnsonelectric.com
B14: Process Engineer: | C14: Heriberto Covarrubias | D14: heriberto.covarrubias@johnsonelectric.com | F14: Process Engineer: | G14: Charlene Gomez | H14: charlene.gomez@johnsonelectric.com
B15: Quality Engineer: | C15: Julieta Solis | D15: julieta.solis@johnsonelectric.com | F15: Quality Engineer: | G15: Akos Korompai | H15: akos.korompai@johnsonelectric.com
B16: Supplier Quality Engineer: | C16: Diego Alonso | D16: diego.alonso@johnsonelectric.com | F16: SCS Purchasing: | G16: Kevin Swisher | H16: kevin.swisher@jonsonelectric.com
B17: SCS Procurement: | C17: Alexis Jara | D17: alexis.jara@johnsonelectric.com | F17: Application Engineer: | G17: Stephen Russano | H17: stephen.russano@johnsonelectric.com
B18: EHS Representative: | C18: Miguel Ruíz | D18: miguelruiz@johnsonelectric.com
B19: Finance Representative: | C19: Alberto Peñalver | D19: alberto.penalver@johnsonelectric.com
B20: Material Management: | C20: Fransisco Díaz | D20: fransisco.diaz@johnsonelectric.com
B21: Foreign trade compliance: | C21: Karime Rivas | D21: karime.rivas@johnsonelectric.com
B22: Training Coordinator: | C22: Luis de la Fuente | D22: luis.delafuente@johnsonelectric.com
B23: Production Representative: | C23: Gustavo Ramirez | D23: gustavo.ramirez@johnsonelectric.com
B24: Customer Quality Engineer: | C24: Jose Fabela | D24: jose.fabela@johnsonelectric.com
B26: Manufacturing site Management | F26: Others (add as needed)
C27: Name | D27: Email | G27: Name | H27: Email
B28: Operations Manager: | C28: Fermin Flores | D28: fermin.flores@johnsonelectric.com | F28: Busines Development Manager: | G28: Philippe Jacquat | H28: philippe.jacquat@johnsonelectric.com
B29: Quality Manager: | C29: Amado Cardona | D29: amado.cardona@johnsonelectroc.com | F29: Senior PM: | G29: Kurt Kromer | H29: Kurt Kromer@johnsonelectric.com
B30: Materials Manager: | C30: Juan Carlos Arizpe | D30: Juancarlos.arizpe@johnsonelectric.com | F30: Maintenance Manager: | G30: Oscar Ramos | H30: oscar.ramos@johnsonelectric.com
B31: SCS Manager: | C31: Kevin Swisher | D31: kevin.swisher@johnsonelectric.com | F31: Engineer Manager: | G31: Olivier Roussel | H31: olivier.roussel@johnsonelectric.com
B32: Finance Manager: | C32: Bernardo Marines | D32: Bernardo.marines@johnsonelectric.com
B33: HR Manager: | C33: Claudia Castañeda | D33: claudia.castaneda@johnsonelectric.com
A39: =+#REF! -> #REF!

Sheet Programa APQP
D1: Información del Proyecto / Project Information
A7: Puntos de JEPDS aplicables / JEPDS applicable items. | C7: Preparación General para el Lanzamiento / Overall launch readiness: | F7: =IF((COUNTIF(J30,"")+COUNTIF(J59,"")+COUNTIF(J78,"")+COUNTIF(J91,"")=39),"",SUM(J30,J59,J78,J91)) -> 75
C8: Día de inicio de producción / SOP date: | F8: =IF('Portada '!D8="","",'Portada '!D8) -> 45609
C9: Champion | D9: Etapas / Stages (APQP) | E9: Entregables / Deliverables | F9: Plan | G9: Control de entregables / Delivereables control: | H9: Status. | I9: Calificación / Score | K9: Observaciones / Remarks
C10: PROJ | D10: ETAPA 2 / STAGE 2 | E10: Equipo multifuncional / CFT (JE Global and internal): | F10: Plan | G10: =+$G$28 -> 45479 | H10: =IF(G10=0, " ", IF(AND(G10<TODAY(),G11=0), "NEEDS ACTION", IF(G11=0,"Ongoing", IF(G11<=G10,"Closed on time", IF(G11>G10,"Closed late"))))) -> Closed on time | I10: =IF(AND(Stage2!C4="",Stage2!D4="",Stage2!E4=""),"",IF(OR(Stage2!C4="X",Stage2!E4="X"),"OK","NG")) -> OK | J10: =IF($I10="","",IF($I10="NG",0,((100/4)/10))) -> 2.5
F11: Real | G11: 45300
C12: DE | E12: DFMEA: | F12: Plan | G12: =+$G$28 -> 45479 | H12: =IF(G12=0, " ", IF(AND(G12<TODAY(),G13=0), "NEEDS ACTION", IF(G13=0,"Ongoing", IF(G13<=G12,"Closed on time", IF(G13>G12,"Closed late"))))) -> Closed on time | I12: =IF(AND(Stage2!C5="",Stage2!D5="",Stage2!E5=""),"",IF(OR(Stage2!C5="X",Stage2!E5=""),"OK","NG")) -> OK | J12: =IF(I12="","",IF(I12="NG",0,((100/4)/10))) -> 2.5
F13: Real | G13: 45300
C14: DE | E14: Lista preliminar de materiales / Preliminary BOM: | F14: Plan | G14: =+$G$28 -> 45479 | H14: =IF(G14=0, " ", IF(AND(G14<TODAY(),G15=0), "NEEDS ACTION", IF(G15=0,"Ongoing", IF(G15<=G14,"Closed on time", IF(G15>G14,"Closed late"))))) -> Closed on time | I14: =IF(AND(Stage2!C6="",Stage2!D6="",Stage2!E6=""),"",IF(OR(Stage2!C6="X",Stage2!E6=""),"OK","NG")) -> OK | J14: =IF(I14="","",IF(I14="NG",0,((100/4)/10))) -> 2.5 | K14: 1. Junta con Diego / Michelle para status de componentes (PPAP de componentes PSW firmado 8 Jul)
F15: Real | G15: 45301
C16: DE | E16: Dibujos / Drawings: | F16: Plan | G16: =+$G$28 -> 45479 | H16: =IF(G16=0, " ", IF(AND(G16<TODAY(),G17=0), "NEEDS ACTION", IF(G17=0,"Ongoing", IF(G17<=G16,"Closed on time", IF(G17>G16,"Closed late"))))) -> Closed late | I16: =IF(COUNTIF(Stage2!C15:E18,"")=12,"",IF(COUNTIF(Stage2!C15:C18,"X")+COUNTIF(Stage2!E15:E18,"X")=4, "OK","NG")) -> OK | J16: =IF(I16="","",IF(I16="NG",0,((100/4)/10))) -> 2.5 | K16: 1. Agregar dibujos a Doc controlados 2. Validar ultima revision en JEPLM para componentes y ensambles 3. Murten (Alessandor) actualizar dibujos torque para atornillado de bracket
F17: Real | G17: 45498
C18: QE/PE | E18: Lista de equipos, fixturas, herramietas, refacciones,gauges e instalaciones necesarias / Lists of equipment, fixtures, tooling, spare parts, gauges and facilities needed. | F18: Plan | G18: =+$G$28 -> 45479 | H18: =IF(G18=0, " ", IF(AND(G18<TODAY(),G19=0), "NEEDS ACTION", IF(G19=0,"Ongoing", IF(G19<=G18,"Closed on time", IF(G19>G18,"Closed late"))))) -> Closed late | I18: =IF(AND(Stage2!C8="",Stage2!D8="",Stage2!E8=""),"",IF(OR(Stage2!C8="X",Stage2!E8=""),"OK","NG")) -> OK | J18: =IF(I18="","",IF(I18="NG",0,((100/4)/10))) -> 2.5 | K18: 1. Actualizar formato oficial / Spare parts list 7 Jun CHN 2. RFQ cotizacion Mauro 3. Gabriel - Equipo de medicion - Leakage test Jit pendiente de confirmar 12 Julio 4. Julieta: Compra de micrometro / caliper / fuente voltaje (Scaner) / Puntas 12 Julio - 16 Agosto - 4 septiembre - 2 Oct 5. Mauro: Colocar PR para compra de partes 12 Julio 6. Fixturas de inyeccion pendientes | L18: Actualizacion de Adam Hall Validar fuente de voltaje equipo de validacion de codigo QR
F19: Real | G19: 45498 | L19: Validar con julieta estatus de fixturas y compra de caliper - Gabriel cotizaciones 20 Sept / Gauge puertos de housing y conector de actuador - Diseño (18 sept) interno SPC atributos
C20: PROJ | E20: Compromiso de Factibilidad del Equipo / Team Feasibility Commitment: | F20: Plan | G20: =+$G$28 -> 45479 | H20: =IF(G20=0, " ", IF(AND(G20<TODAY(),G21=0), "NEEDS ACTION", IF(G21=0,"Ongoing", IF(G21<=G20,"Closed on time", IF(G21>G20,"Closed late"))))) -> Closed late | I20: OK | J20: =IF(I20="","",IF(I20="NG",0,((100/4)/10))) -> 2.5 | K20: 1. Pendiente de firmas 31 May, firmas completas interno (ZAC), en firmas diseño 26 Julio
F21: Real | G21: 45512
C22: ALL | E22: Lecciones aprendidas/ Lessons learned. | F22: Plan | G22: =+$G$28 -> 45479 | H22: =IF(G22=0, " ", IF(AND(G22<TODAY(),G23=0), "NEEDS ACTION", IF(G23=0,"Ongoing", IF(G23<=G22,"Closed on time", IF(G23>G22,"Closed late"))))) -> Closed late | I22: OK | J22: =IF(I22="","",IF(I22="NG",0,((100/4)/10))) -> 2.5 | K22: 1. Julieta S. - Lecciones aprendidas de otras localidades con Valvulas (Wuxi) 19 Julio Contaminacion de particulas en valvula 2. Jesus compartir Lecciones aprendidas Murten 3. Lecciones aprendidas para los productos en curso 22 Julio
F23: Real | G23: 45546
C24: PROJ | E24: Manual de Proveedor / Customer Supplier Manual | F24: Plan | G24: =+$G$28 -> 45479 | H24: =IF(G24=0, " ", IF(AND(G24<TODAY(),G25=0), "NEEDS ACTION", IF(G25=0,"Ongoing", IF(G25<=G24,"Closed on time", IF(G25>G24,"Closed late"))))) -> Closed on time | I24: =IF(AND(Stage2!C12="",Stage2!D12="",Stage2!E12=""),"",IF(OR(Stage2!C12="X",Stage2!E12="X"),"OK","NG")) -> OK | J24: =IF(I24="","",IF(I24="NG",0,((100/4)/10))) -> 2.5 | K24: 1. Pendiente de confrimar Manual ultima revision
F25: Real | G25: 45457
C26: DE | E26: Reporte de Validación del Diseño / DV Report | F26: Plan | G26: =+$G$28 -> 45479 | H26: =IF(G26=0, " ", IF(AND(G26<TODAY(),G27=0), "NEEDS ACTION", IF(G27=0,"Ongoing", IF(G27<=G26,"Closed on time", IF(G27>G26,"Closed late"))))) -> Closed on time | I26: OK | J26: =IF(I26="","",IF(I26="NG",0,((100/4)/10))) -> 2.5
F27: Real | G27: 45292
C28: QE | E28: Lista preliminar de características del cliente / Preliminary Customer Characteristics List: | F28: Plan | G28: =+G31-32 -> 45479 | H28: =IF(G28=0, " ", IF(AND(G28<TODAY(),G29=0), "NEEDS ACTION", IF(G29=0,"Ongoing", IF(G29<=G28,"Closed on time", IF(G29>G28,"Closed late"))))) -> Closed on time | I28: =IF(AND(Stage2!C16="",Stage2!D16="",Stage2!E16=""),"",IF(OR(Stage2!C16="X",Stage2!E16="X"),"OK","NG")) -> OK | J28: =IF(I28="","",IF('Programa APQP'!I28:I29="NG",0,((100/4)/10))) -> 2.5 | K28: 1. Gabriel pendiente de documentar 31 May
F29: Real | G29: 45442
E30: Entregables/ Deliverables | H30: DECISION | I30: OK | J30: =IF(SUM(J10:J29)="","",SUM(J10:J29)) -> 25
C31: QE | D31: Stage 3'!Print_Area | E31: 00.- Checklist de inspección de entrada / Incoming Inspection Checklist | F31: Plan | G31: =+$G$57 -> 45511 | H31: =IF(G31=0, " ", IF(AND(G31<TODAY(),G32=0), "NEEDS ACTION", IF(G32=0,"Ongoing", IF(G32<=G31,"Closed on time", IF(G32>G31,"Closed late"))))) -> Closed on time | I31: OK | J31: =IF(I31="","",IF(I31="NG",0,((100/4)/14))) -> 1.7857143 | K31: Gabriel Pendiente brackets Plan para componentes Inyectados
F32: Real | G32: 45397
A33: 3.18 | C33: PE | E33: 01.- Especificaciones de empaque / Packaging specifications | F33: Plan | G33: =+$G$57 -> 45511 | H33: =IF(G33=0, " ", IF(AND(G33<TODAY(),G34=0), "NEEDS ACTION", IF(G34=0,"Ongoing", IF(G34<=G33,"Closed on time", IF(G34>G33,"Closed late"))))) -> Closed on time | I33: =IF(AND(Stage2!C21="",Stage2!D21="",Stage2!E21=""),"",IF(OR(Stage2!C21="X",Stage2!E21="X"),"OK","NG")) -> OK | J33: =IF(I33="","",IF(I33="NG",0,((100/4)/14))) -> 1.7857143 | K33: HD Terminado
F34: Real | G34: 45427 | L34: DT WS pendiente especificacion
A35: 3.19 | C35: QE | E35: 02.-Cambios en el SGC para fabricar el producto / Changes in the QMS for product manufacturing: | F35: Plan | G35: =+$G$57 -> 45511 | H35: =IF(G35=0, " ", IF(AND(G35<TODAY(),G36=0), "NEEDS ACTION", IF(G36=0,"Ongoing", IF(G36<=G35,"Closed on time", IF(G36>G35,"Closed late"))))) -> Closed late | I35: =IF(AND(Stage2!C23="",Stage2!D23="",Stage2!E23=""),"",IF(OR(Stage2!C23="X",Stage2!E23="X"),"OK","NG")) -> OK | J35: =IF(I35="","",IF(I35="NG",0,((100/4)/14))) -> 1.7857143 | K35: 1. Julieta S. Dar a conocer con el equipo 16 agosto - 3 Septiembre 2. Auditoria Personalizada (por capas) especifica Stellantis Manuel / Rodrigo R.
F36: Real | G36: 45512
A37: 2.24 | C37: PE | E37: 03.- Diagrama de flujo de proceso / Process Flow Chart: | F37: Plan | G37: 45513 | H37: =IF(G37=0, " ", IF(AND(G37<TODAY(),G38=0), "NEEDS ACTION", IF(G38=0,"Ongoing", IF(G38<=G37,"Closed on time", IF(G38>G37,"Closed late"))))) -> Closed late | I37: OK | J37: =IF(I37="","",IF(I37="NG",0,((100/4)/14))) -> 1.7857143 | K37: 1. Validar ultima revision con Jesus y Gabriel (Junta semanal Control Plan, PFMEA) 2. Controlar documento 3rd week september - 1ra semana Octubre
F38: Real | G38: 45544
A39: 2.25 | C39: PE | E39: 04.- Disposición de piso / Floor plan layout: | F39: Plan | G39: =+$G$57 -> 45511 | H39: =IF(G39=0, " ", IF(AND(G39<TODAY(),G40=0), "NEEDS ACTION", IF(G40=0,"Ongoing", IF(G40<=G39,"Closed on time", IF(G40>G39,"Closed late"))))) -> Closed on time | I39: =IF(AND(Stage2!C26="",Stage2!D26="",Stage2!E26=""),"",IF(OR(Stage2!C26="X",Stage2!E26="x"),"OK","NG")) -> OK | J39: =IF(I39="","",IF(I39="NG",0,((100/4)/14))) -> 1.7857143 | K39: Layout completado pendiente de controlar SWS pendiente (PDF, Confirmar linea atornillado)
F40: Real | G40: 45464
A41: 3.11 | C41: QE/PE | E41: 05.- Matriz de características / Characteristics Matrix | F41: Plan | G41: =+$G$57 -> 45511 | H41: =IF(G41=0, " ", IF(AND(G41<TODAY(),G42=0), "NEEDS ACTION", IF(G42=0,"Ongoing", IF(G42<=G41,"Closed on time", IF(G42>G41,"Closed late"))))) -> Closed on time | I41: OK | J41: =IF(I41="","",IF(I41="NG",0,((100/4)/14))) -> 1.7857143 | K41: Jesus / Gabriel 31 Mayo Proceso y producto cerrado
F42: Real | G42: 45450
A43: 3.12 | C43: PE | E43: 0.6- PFMEA | F43: Plan | G43: 45513 | H43: =IF(G43=0, " ", IF(AND(G43<TODAY(),G44=0), "NEEDS ACTION", IF(G44=0,"Ongoing", IF(G44<=G43,"Closed on time", IF(G44>G43,"Closed late"))))) -> Closed late | I43: OK | J43: =IF(I43="","",IF(I43="NG",0,((100/4)/14))) -> 1.7857143 | N43: 1. Revision diaria (preeliminar 5 agosto) 2. Evaluar screwdriver line (4 septiembre) - 11 Sept - 1ra semana Octubre
F44: Real | G44: 45544
A45: 3.16 | C45: QE | E45: 07.- Plan de Control de pre-lanzamiento / Pre-launch Control Plan | F45: Plan | G45: 45513 | H45: =IF(G45=0, " ", IF(AND(G45<TODAY(),G46=0), "NEEDS ACTION", IF(G46=0,"Ongoing", IF(G46<=G45,"Closed on time", IF(G46>G45,"Closed late"))))) -> Closed on time | I45: OK | J45: =IF(I45="","",IF(I45="NG",0,((100/4)/14))) -> 1.7857143 | N45: 1. Revision diaria (preeliminar 5 agosto) 2. Evaluar screwdriver line (4 septiembre) - 11 Sept - 1ra semana Octubre
...

Sheet DATA
C1: Project leader: | D1: E-MAIL
C2: Giovanna Leal | D2: Giovanna.leal@johnsonelectric.com
C3: Andrea Herrera | D3: Andrea.herrera@johnsonelectric.com
A4: Process Engineer: | B4: G3.0 | C4: Roberto Ramos | D4: Roberto.ramos@johnsonelectric.com
B5: G3S | C5: Roberto Ramos | D5: Roberto.ramos@johnsonelectric.com
B6: G3.5 | C6: Roberto Ramos | D6: Roberto.ramos@johnsonelectric.com
B7: STW | C7: Felipe Ornelas | D7: Felipe.ornelas@johnsonelectric.com
B8: EVD | C8: Mario Silva | D8: Mario.silva@johnsonelectric.com
B9: EXB | C9: Mario Silva | D9: Mario.silva@johnsonelectric.com
B10: HP
B11: LAMINATION | C11: Carlos Ramos | D11: Carlos.ramos@johnsonelectric.com
B12: INJECTION | C12: Luis Sánchez | D12: Luis.sanchez@johnsonelectric.com
B13: CFM | C13: Luis Cortés | D13: Luis.cortes@johnsonelectric.com
A14: Quality Engineer: | B14: G3.0 | C14: Guadalupe Reyes | D14: Guadalupe.reyes@johsonelectric.com
B15: G3S | C15: Ricardo Rivas | D15: Ricardo.rivas@johnsonelectric.com
B16: G3.5 | C16: Elias Varela | D16: Elias.varela@johnsonelectric.com
B17: STW | C17: Guadalupe Reyes | D17: Guadalupe.reyes@johsonelectric.com
B18: HP
B19: EVD | C19: Guadalupe Reyes | D19: Guadalupe.reyes@johsonelectric.com
B20: EXB | C20: Guadalupe Reyes | D20: Guadalupe.reyes@johsonelectric.com
B21: LAMINATION | C21: Elias Varela | D21: Elias.varela@johsonelectric.com
B22: INJECTION | C22: Elias Varela | D22: Elias.varela@johsonelectric.com
B23: CFM | C23: Socorro Castillo | D23: Socorro.castillo@johnsonelectric.com
A24: Supplier Quality Engineer: | C24: Diego Alonso | D24: Diego.alonso@johnsonelectric.com
C25: Diego Alonso | D25: Diego.alonso@johnsonelectric.com
A26: Material management: | C26: Adrianna Miramontes | D26: Adrianna.miramontes@johnsonelectric.com
C27: Adrianna Miramontes | D27: Adrianna.miramontes@johnsonelectric.com
A28: SCS Procurement: | C28: Eliazar González | D28: Eliazar.gonzalez@johnsonelectric.com
A29: EHS Representative: | C29: Noel Ramírez | D29: Noel.ramirez@johnsonelectric.com
A30: Finance rep: | C30: Alejandra Villa | D30: Alejandra.villa@johnsonelectric.com
A31: Foreign trade compliance | C31: Mireya Ramírez | D31: Mireya.ramirez@johnsoneeltric.com
A32: Material Management: | C32: Adrianna Miramontes | D32: Adrianna.miramontes@johnsonelectric.com
A33: Training Coordinator: | C33: Goretti Pérez | D33: Goretti.perez@johnsonelectric.com
A34: Production Representative: | C34: Carlos Jiménez | D34: Carlos.jiménez@johnsonelectric.com
C35: Fermin Flores | D35: Fermin.flores@johnsonelectric.com
A36: Customer Quality Engineer: | C36: Nora Ramírez | D36: Nora.ramirez@johnsonelectric.com
A37: Customer Quality Engineer: | C37: Julieta Solis | D37: Julieta.solis@johnsonelectric.com
A41: Jean Christophe Melmies | B41: Jean.christophe.melmies@johnsonelectric.com
A42: Carlos Torres | B42: Carlos.torres@johnsonelectric.com
A43: Juan Carlos Arizpe | B43: Juancarlos.arizpe@johnsonelectric.com
...

Sheet Stage2
B1: =+#REF! -> #REF! | E1: NOTA: Cualquier N/A debe ser justificado en los comentarios NOTE: Any N/A found must be justified in the comments.
B2: Requisito / Requirement | C2: Si / Yes | D2: No | E2: N/A | F2: Comentarios/Acción requerida / Comments/Action required | G2: Responsable / Responsible | H2: Fecha / Date
A3: Información preliminar/ Preliminary information
A4: 1 | B4: ¿Se cuenta con un CFT completado? / Is there a CFT completed? | C4: X | G4: =+'Portada '!$A$15 -> Ingeniero de Proyectos / Project Engineer
A5: 2 | B5: ¿Se cueta con el DFMEA completo? / Is there a DFMEA completed? | C5: X | G5: Ingeniero de diseño / Design Engineer
A6: 3 | B6: ¿Se cuenta con un BOM Preliminar? / Is there a Preliminary BOM? | C6: X | G6: Ingeniero de diseño / Design Engineer
A7: 4 | B7: ¿Los dibujos están disponibles? / Are the drawings availables? | D7: X | F7: Pendiente dibujos de empaque terminados | G7: Ingeniero de diseño / Design Engineer
A8: 5 | B8: ¿Se cuenta con las listas del equipo disponibles? / Are equipment lists available? | C8: X | F8: Compartido por China ya en carpeta APQP | G8: QE/PE
A9: 6 | B9: ¿Se cuenta con un Team Feasibility Commitment firmado? / Is there a Team Feasibility Commitment signed? | D9: X | F9: Pendiente de firmas | G9: =+'Portada '!$A$15 -> Ingeniero de Proyectos / Project Engineer
A10: 7 | B10: ¿Hay lecciones aprendidas documentadas?/ Are there lessons learnt documented? | G10: QE/PE
A11: 8 | B11: ¿Se cuenta con el Manual de Proveedor? / Is there a Customer Supplier Manual? | C11: X | F11: Ya en carpeta APQP | G11: =+'Portada '!$A$15 -> Ingeniero de Proyectos / Project Engineer
A12: 9 | B12: ¿Se proporcionó el Reporte DV?/ Was The DV Report provided? | C12: X | F12: Ya en carpeta APQP | G12: Ingeniero de diseño / Design Engineer
A13: 10 | B13: ¿Se cuenta con el dibujo de cliente?/ Is the Customer Drawing available? | D13: X | F13: Se solicitara dibujos de cliente | G13: =+'Portada '!$A$15 -> Ingeniero de Proyectos / Project Engineer
A14: Dibujos Ingenieriles / Engineering Drawings
A15: 11 | B15: ¿Están las características especiales marcadas en el dibujo y soportadas en el plan de control? / Are special characteristics marked in the drawing and supported in control plan? | C15: X | G15: =+'Portada '!$A$15 -> Ingeniero de Proyectos / Project Engineer
A16: 12 | B16: ¿Puede la tecnología de inspección medir todos los requerimientos del dibujo? / Can inspection technology measure all design requirements? | C16: X | G16: =+'Portada '!$A$15 -> Ingeniero de Proyectos / Project Engineer
A17: 13 | B17: ¿Las tolerancias son compatibles con los estándares de manufactura? DIN ISO 2768 / Are tolerances compatible with accepted manufacturing standards? | C17: X | G17: =+'Portada '!$A$15 -> Ingeniero de Proyectos / Project Engineer
A18: 14 | B18: ¿El cliente aprobó el dibujo de JE? / Customer approved the JE drawing? | C18: X | G18: =+'Portada '!$A$15 -> Ingeniero de Proyectos / Project Engineer
A19: Componentes nuevos / New components
A20: 15 | B20: ¿La lista de los componentes nuevos se encuentra disponible? / Is the list of new components available? (New components format) | C20: X | F20: Sourcing Strategy | G20: =+'Portada '!$A$15 -> Ingeniero de Proyectos / Project Engineer
A21: 16 | B21: ¿Esta lista está alineada con el archivo de seguimiento de RFQ de procuramiento? Is this list aligned with the RFQ tracker file from procurement? | C21: X | G21: Procuramiento de SCS / SCS Procurement
A22: 17 | B22: ¿Se conocen los proveedores de los nuevos materiales? / Are new materials suppliers known? | C22: X | G22: Procuramiento de SCS / SCS Procurement
A23: 18 | B23: ¿Las características especiales del material son identificadas? / Are special material characteristics identified? | C23: X | G23: =+'Portada '!$A$15 -> Ingeniero de Proyectos / Project Engineer
A24: 19 | B24: ¿Se ha considerado el tiempo de entrega de los materiales en los milestones? / Has lead time of materials been considerated in milestones? | C24: X | G24: Procuramiento de SCS / SCS Procurement
A25: 20 | B25: ¿Se cuentan con todas las QRs aplicables para nuevos componentes disponibles ? / Do applicable QRs exist for new components availability? | G25: Procuramiento de SCS / SCS Procurement
A26: 21 | B26: ¿Los TP de nuevos componentes están disponibles? / Are New components TP available? | C26: X | G26: Representante de finanzas / Finance representative
A27: Lista preliminar de características del cliente / Preliminary Customer Characteristics List:
A28: 22 | B28: ¿La lista preliminar de características del cliente se encuentra disponible? / Is the list opreliminary customer characteristics available? (New components format) | D28: X | G28: Ingeniero de diseño / Design Engineer
A29: 23 | B29: ¿Esta lista se encuentra avalada por la firma del cliente? / Is this list endorsed by customer signature? | D29: X | G29: Ingeniero de diseño / Design Engineer

Sheet 00
E1: NOTA: Cualquier N/A debe ser justificado en los comentarios NOTE: Any N/A found must be justified in the comments.
B2: Requisito / Requirement | C2: Si / Yes | D2: No | E2: N/A | F2: Comentarios/Acción requerida / Comments/Action required | G2: Responsable / Responsible | H2: Fecha / Date
A3: 1 | B3: ¿Se tiene un dibujo congelado con la última revisión para completar el IICL? / Is there a frozen drawing with the last revision to complete the IICL? | C3: X | G3: =+'Portada '!$A$15 -> Ingeniero de Proyectos / Project Engineer
A4: 2 | B4: ¿Se cuenta con el formato de IICL para los nuevos componentes? / Is the IICL for new components available? | C4: X | G4: =+'Portada '!$A$16 -> Ingeniero de Calidad / QE
A5: 3 | B5: ¿Se cuenta con el paquete PPAP y PSW de los nuevos componentes? / Is PPAP package and PSW for new components available? | D5: X | F5: Pendiente Valve Seal WK40 | G5: Ingeniero de Calidad de Proveedores / Supplier Quality Engineer
A6: 4 | B6: ¿El IMDS correcto de los componentes está disponible en el portal de JEMX? / Is the right IMDS available in JEMX portal? | C6: X | G6: Ingeniero de Calidad de Proveedores / Supplier Quality Engineer

Sheet 01
E1: NOTA: Cualquier N/A debe ser justificado en los comentarios NOTE: Any N/A found must be justified in the comments.
B2: Requisito / Requirement | C2: Si / Yes | D2: No | E2: N/A | F2: Comentarios/Acción requerida / Comments/Action required | G2: Responsable / Responsible | H2: Fecha / Date
A3: 1 | B3: ¿Se cuentan con especificaciones de empaque del cliente? / Is packaging specification from customer available? | C3: X | G3: =+'Portada '!$A$17 -> Process Engineer / PE
A4: 2 | B4: ¿El empaque mantiene el rendimiento y características del producto durante el empaque, tránsito y desempaque? / Does packaging keep the performance and product characteristics during packaging, transit and unpackaging? | C4: X | G4: =+'Portada '!$A$17 -> Process Engineer / PE
A5: 3 | B5: ¿Se consideran las especificaciones desde el pallet hasta las particiones internas? / Are considered the specifications from the pallet to the internal partitions? | C5: X | G5: =+'Portada '!$A$17 -> Process Engineer / PE
A6: 4 | B6: ¿Se consideran las regulaciones del empaque para los países a los que se exportará el producto? / Are considered packaging regulations for the countries to which the product will be exported? | C6: X | G6: =+'Portada '!$A$17 -> Process Engineer / PE

Sheet 02
E1: NOTA: Cualquier N/A debe ser justificado en los comentarios NOTE: Any N/A found must be justified in the comments.
B2: Requisito / Requirement | C2: Si / Yes | D2: No | E2: N/A | F2: Comentarios/Acción requerida / Comments/Action required | G2: Responsable / Responsible | H2: Fecha / Date
A3: 1 | B3: ¿Son requeridos cambios en el SGC para producir el producto? / Are changes required in the QMS for product manufacturing? | D3: X | F3: Cambios no requeridos | G3: =+'Portada '!$A$16 -> Ingeniero de Calidad / QE
A4: 2 | B4: ¿Se conoce quién es el contacto de calidad con el cliente? / Is customer quality contact known? | C4: X | G4: =+'Portada '!$A$16 -> Ingeniero de Calidad / QE
A5: 3 | B5: ¿Se conoce quién es el contacto de calidad con proveedores? / Is Suppliers Quality contact known? | C5: X | G5: =+'Portada '!$A$16 -> Ingeniero de Calidad / QE
A6: 4 | B6: ¿Se conocen los requerimientos específicos del cliente? (manual de proveedor) / Are customer specific requirements known? (supplier manual)? | C6: X | G6: =+'Portada '!$A$16 -> Ingeniero de Calidad / QE

Sheet 03
E1: NOTA: Cualquier N/A debe ser justificado en los comentarios NOTE: Any N/A found must be justified in the comments.
B2: Requisito / Requirement | C2: Si / Yes | D2: No | E2: N/A | F2: Comentarios/Acción requerida / Comments/Action required | G2: Responsable / Responsible | H2: Fecha / Date | I2: Solicitar los siguientes formatos a DCC / Request DCC the following formats | J2: F7511
A3: 1 | B3: ¿Ilustra el diagrama de flujo la secuencia de producción completa desde la recepción hasta el embarque incluyendo los procesos y servicios que lo soportan? / Does Flowchart show the full production sequence from receipt to shipping including those processes and services supporting it? | C3: X | G3: =+'Portada '!$A$17 -> Process Engineer / PE
A4: 2 | B4: ¿Se incluyen en el diagrama de flujo los puntos de revisión del plan de control y PFMEA? / Are checkpoints of PCP and PFMEA included in the flowchart? | D4: X | F4: Pendiente de revision | G4: =+'Portada '!$A$17 -> Process Engineer / PE
A5: 3 | B5: ¿El diagrama de flujo muestra el tipo de traslado del producto entre operaciones? / Is transfer type of product between operations shown in flow chart? | C5: X | F5: Ya en carpetas APQP | G5: =+'Portada '!$A$17 -> Process Engineer / PE
A6: 4 | B6: ¿El diagrama de flujo ha sido controlado? / Have been Process flow chart controlled? | D6: X | G6: =+'Portada '!$A$17 -> Process Engineer / PE

Sheet 04
E1: NOTA: Cualquier N/A debe ser justificado en los comentarios NOTE: Any N/A found must be justified in the comments.
B2: Requisito / Requirement | C2: Si / Yes | D2: No | E2: N/A | F2: Comentarios/Acción requerida / Comments/Action required | G2: Responsable / Responsible | H2: Fecha / Date
A3: 1 | B3: ¿Se identifican todos los procesos y los puntos de inspección requeridos? / Are all required processes and inspection points identified? | C3: X | G3: =+'Portada '!$A$17 -> Process Engineer / PE
A4: 2 | B4: ¿Han sido claramente identificadas las áreas para todo el material y el equipo necesario para cada operación en la distribución de piso? / Have clearly marked areas for all material and equipment needed at each operation been identified in layout distribution? | C4: X | G4: =+'Portada '!$A$17 -> Process Engineer / PE
A5: 3 | B5: ¿Hay suficiente espacio para todo el equipo? / There is enough space for all equipment? | C5: X | G5: =+'Portada '!$A$17 -> Process Engineer / PE
A6: 4 | B6: ¿Las áreas de inspección son del tamaño e iluminación adecuada? / Have the inspection areas a proper dimension and lighting ? | C6: X | G6: =+'Portada '!$A$17 -> Process Engineer / PE
A7: 5 | B7: ¿Las áreas de retención son adecuadas? / Are retention areas adequate? | C7: X | G7: =+'Portada '!$A$17 -> Process Engineer / PE
A8: 6 | B8: ¿Los puntos de inspección están localizados para prevenir el envío de productos no conformes? / Are inspection points located to prevent shipment of nonconforming products? | C8: X | G8: =+'Portada '!$A$17 -> Process Engineer / PE
A9: 7 | B9: ¿Son los procesos libres de agentes contaminantes? / Are processes free of contaminating agents? | C9: X | G9: =+'Portada '!$A$17 -> Process Engineer / PE
A10: 8 | B10: ¿Son los procesos diseñados para evitar la mezcla de productos? / Are the processes designed to avoid products mix? | C10: X | G10: =+'Portada '!$A$17 -> Process Engineer / PE
A11: 9 | B11: ¿Se ha realizado el formato de requisición de personal necesario? / Has headcount format been made to request needed DL? | C11: X | G11: =+'Portada '!$A$17 -> Process Engineer / PE
A12: 10 | B12: ¿Se cuenta con el plan de reclutamiento disponible por parte de RH? / Is recruitment plan by HR available? | C12: X | G12: Coordinador de Entrenamiento / Training Coordinator
A13: 11 | B13: ¿Ha sido controlado como "Pre-producción"? / Have been it controlled as "Pre-production"? | C13: X | G13: =+'Portada '!$A$17 -> Process Engineer / PE

Sheet 05
E1: NOTA: Cualquier N/A debe ser justificado en los comentarios NOTE: Any N/A found must be justified in the comments.
B2: Requisito / Requirement | C2: Si / Yes | D2: No | E2: N/A | F2: Comentarios/Acción requerida / Comments/Action required | G2: Responsable / Responsible | H2: Fecha / Date | I2: Solicitar los siguientes formatos a DCC / Request DCC the following formats | J2: F7332B
A3: 1 | B3: ¿Se establece la relación entre las operaciones del proceso y las características del producto? / Is the relationship between process and product characteristics established? | C3: X | G3: =+'Portada '!$A$17 -> Process Engineer / PE
A4: 2 | B4: ¿Se identifican aquellas características criticas? / Are critical characteristics identified? | C4: X | G4: =+'Portada '!$A$17 -> Process Engineer / PE
A5: 3 | B5: ¿Ha sido controlado? / Have been it controlled? | D5: X | F5: 3rd wk september | G5: =+'Portada '!$A$17 -> Process Engineer / PE

Sheet 06
E1: NOTA: Cualquier N/A debe ser justificado en los comentarios NOTE: Any N/A found must be justified in the comments.
B2: Requisito / Requirement | C2: Si / Yes | D2: No | E2: N/A | F2: Comentarios/Acción requerida / Comments/Action required | G2: Responsable / Responsible | H2: Fecha / Date | I2: Solicitar los siguientes formatos a DCC / Request DCC the following formats | J2: F7332 F7514G
A3: 1 | B3: ¿El PFMEA se preparó por el CFT?/ Was the PFMEA prepared by CFT? | C3: X | G3: =+'Portada '!$A$17 -> Process Engineer / PE
A4: 2 | B4: ¿Se han considerado controles apropiados para atender los modos de falla? / Have appropriate controls been considered to attend all the failure modes? | C4: X | G4: =+'Portada '!$A$17 -> Process Engineer / PE
A5: 3 | B5: ¿Todas las operaciones enlistadas en el PFMEA coinciden con el Flow Chart? / Are all the operations listed in PFMEA matching with Flow Chart? | C5: X | G5: =+'Portada '!$A$17 -> Process Engineer / PE
A6: 4 | B6: ¿Se marcan de manera consitente las características especiales de acuerdo a la simbología y requerimientos del cliente y/o dibujos? / Are special characteristics marked and are consistent with the symbolism, customer requirements and/or drawings? | C6: X | G6: =+'Portada '!$A$17 -> Process Engineer / PE
A7: 5 | B7: ¿La revisión corresponde a la definida en los dibujos? / Does revision correspond to the defined in drawings? | C7: X | G7: =+'Portada '!$A$17 -> Process Engineer / PE
A8: 6 | B8: ¿Son los planes de mantenimiento preventivo derivados del análisis del PFMEA? / Are preventive maintanance plans derived from PFMEA? | C8: X | G8: =+'Portada '!$A$17 -> Process Engineer / PE
A9: 7 | B9: ¿Los valores para la evaluación de SOD están refereciados al manual de la AIAG? / The values for the SOD evaluation are referenced to the AIAG Manual? | C9: X | G9: =+'Portada '!$A$17 -> Process Engineer / PE
A10: 8 | B10: ¿El nivel de prioridad se decide en base al Método de límite de riesgo (RLM)? / Is priority level based on the Risk Limit Method? | C10: X | G10: =+'Portada '!$A$17 -> Process Engineer / PE
A11: 9 | B11: ¿Existen acciones definidas para la disminución del riesgo para el top identificado? / Does defined actions exist for the top risk decrease? | C11: X | G11: =+'Portada '!$A$17 -> Process Engineer / PE
A12: 10 | B12: ¿Las acciones están enfocadas hacia la reducción del nivel de prioridad "más bajo riesgo (3)"? / Is the aim for the actions focused towards the reduction of priority level "lowest risk (3)"? | C12: X | G12: =+'Portada '!$A$17 -> Process Engineer / PE
A13: 11 | B13: ¿Las matrices del nivel de prioridad se usan correctamente? / Are priority level matrices used correctly? | C13: X | G13: =+'Portada '!$A$17 -> Process Engineer / PE
A14: 12 | B14: ¿La fórmula para el cálculo del RPN es la correcta? (SxOxD) / Is the formula for the calculation of RPN correct? (SxOxD) | C14: X | G14: =+'Portada '!$A$17 -> Process Engineer / PE
A15: 13 | B15: ¿Ha sido controlado? / Have been it controlled? | C15: X | G15: =+'Portada '!$A$17 -> Process Engineer / PE

Sheet 07
E1: NOTA: Cualquier N/A debe ser justificado en los comentarios NOTE: Any N/A found must be justified in the comments.
B2: Requisito / Requirement | C2: Si / Yes | D2: No | E2: N/A | F2: Comentarios/Acción requerida / Comments/Action required | G2: Responsable / Responsible | H2: Fecha / Date | I2: Solicitar los siguientes formatos a DCC / Request DCC the following formats | J2: F7511
A3: 1 | B3: ¿Son los controles identificados en el PFMEA incluidos en el plan de control? / Are the controls identified in the PFMEA included in the control plan? | C3: X | G3: =+'Portada '!$A$16 -> Ingeniero de Calidad / QE
A4: 2 | B4: ¿Todas las operaciones y estaciones son trazables entre FMEA, Process Flow Chart y Control Plan? / Are all operations and stations traceable between PFMEA, Process Flow Chart and Control Plan? | C4: X | G4: =+'Portada '!$A$16 -> Ingeniero de Calidad / QE
A5: 3 | B5: ¿Se identifican los requerimientos de pruebas de ingeniería y dimensionales en el plan de control? / Are the requirements for engineering and dimensional tests identified in the control plan? | C5: X | G5: =+'Portada '!$A$16 -> Ingeniero de Calidad / QE
A6: 4 | B6: ¿Están disponibles los equipos de pruebas y gages marcados en el plan de control? / Are test equipment and gages listed in control plan available? | C6: X | G6: =+'Portada '!$A$16 -> Ingeniero de Calidad / QE
A7: 5 | B7: ¿Se define la cantidad de piezas necesaria para pruebas? / Is defined necessary quantity of pieces for tests? | C7: X | G7: =+'Portada '!$A$16 -> Ingeniero de Calidad / QE
A8: 6 | B8: ¿Son los planes de control correctamente identificados para pre-lanzamiento? / Are control plans properly identified as pre-launch? | C8: X | G8: =+'Portada '!$A$16 -> Ingeniero de Calidad / QE
A9: 7 | B9: ¿La revisión corresponde a la definida en los dibujos? / Does revision correspond to the defined in drawings? | C9: X | G9: =+'Portada '!$A$16 -> Ingeniero de Calidad / QE
A10: 8 | B10: ¿Se marcan de manera consitente las características especiales de acuerdo a la simbología y requerimientos del cliente y/o dibujos? / Are special characteristics marked and are consistent with the symbolism, customer requirements and/or drawings? | C10: X | G10: =+'Portada '!$A$16 -> Ingeniero de Calidad / QE
A11: 9 | B11: ¿Existen planes de reacción definidos en el plan de control y son realizables? / Are achievable reaction plans defined in control plan? | C11: X | G11: =+'Portada '!$A$16 -> Ingeniero de Calidad / QE
A12: 10 | B12: Si se requiere, el cliente ha aprobado el plan de control? / If required, has the customer approved the control plan? | C12: X | G12: =+'Portada '!$A$16 -> Ingeniero de Calidad / QE
B13: ¿El Control Plan hace referencia a los parámetros de procesos listados en la Matriz de Características? / Does Control Plan reference to the process parameters listed in the Characteristic Matrix? | C13: X | G13: =+'Portada '!$A$16 -> Ingeniero de Calidad / QE
A14: 12 | B14: ¿Ha sido controlado? / Have been it controlled? | C14: X | G14: =+'Portada '!$A$17 -> Process Engineer / PE

Sheet 08
I1: NOTA: Cualquier N/A debe ser justificado en los comentarios NOTE: Any N/A found must be justified in the comments.
B2: Requisito / Requirement | C2: Si / Yes | F2: No | I2: N/A | L2: Comentarios/Acción requerida / Comments/Action required | M2: Responsable / Responsible | N2: Fecha / Date | O2: Solicitar los siguientes formatos a DCC / Request DCC the following formats | P2: F7512A WI 7512B II F7514M PMWI F7512B QICL F8530 VA
C3: Calidad / Quality | D3: Procesos / Processes | E3: Mantenimiento / Maintenance | F3: Calidad / Quality | G3: Procesos / Processes | H3: Mantenimiento / Maintenance | I3: Calidad / Quality | J3: Procesos / Processes | K3: Mantenimiento / Maintenance
A4: 1 | B4: ¿Las instrucciones aplicables están disponibles para todas las operaciones/inspecciones? / Are applicable instructions available? | C4: X | D4: X | E4: X | M4: PE / QE / MT
A5: 2 | B5: ¿Se incluyen imágenes y diagramas en las instrucciones? / Are pictures and diagrams included in WI? | C5: X | D5: X | E5: X | M5: PE / QE / MT
A6: 3 | B6: ¿Se cuenta con instrucciones de inspección? / Are inspection instructions available? | C6: X | D6: X | M6: PE / QE / MT
A7: 4 | B7: ¿Se determinan las frecuencias de las acciones conforme al plan de control y FMEA? / Are actions frequencies determined according to control plan and FMEA? | C7: X | D7: X | E7: X | M7: PE / QE / MT
A8: 5 | B8: ¿Se determinan el número de muestras conforme al plan de control y FMEA? / Are sample sizes determined according to control plan and FMEA? | C8: X | D8: X | M8: PE / QE / MT
A9: 6 | B9: ¿Existen planes de reacción documentados en caso de detección de alguna no conformidad? / Are reaction plans documented in case a non-conformance detected? | C9: X | D9: X | E9: X | M9: PE / QE / MT
A10: 7 | B10: ¿Número de documento es legible y rastreable? / Is document number legible and traceable? | C10: X | D10: X | E10: X | M10: PE / QE / MT
A11: 8 | B11: ¿Las instrucciones cuentan con el sello de documento controlado? / Are these instructions stamped as controlled document? | C11: X | D11: X | E11: X | M11: PE / QE / MT
A12: 9 | B12: ¿Se encuentran las instrucciones disponibles en el área de trabajo? / Are instructions available in work area? | C12: X | D12: X | E12: X | M12: PE / QE / MT
A13: 10 | B13: ¿Se cuentan disponibles los manuales de maquinaria y proceso? / Are machinery and process manuals available? | D13: X | E13: X | M13: PE / MT
A14: 11 | B14: ¿Se cuenta con evaluación documentada del entrenamiento y evaluación de los empleados en estas instrucciones de trabajo? / A documented training assessment for employees about work instructions exist? | D14: X | M14: Coordinador de entenamiento / Training Coordinator

Sheet 09
E1: NOTA: Cualquier N/A debe ser justificado en los comentarios NOTE: Any N/A found must be justified in the comments.
B2: Requisito / Requirement | C2: Si / Yes | D2: No | E2: N/A | F2: Comentarios/Acción requerida / Comments/Action required | G2: Responsable / Responsible | H2: Fecha / Date | I2: Solicitar los siguientes formatos a DCC / Request DCC the following formats | J2: F7360
A3: 1 | B3: ¿Se desarrolla el plan del Análisis del Sistema de Medición a partir del plan de control? / Is a MSA plan developed according to Control Plan? | C3: X | G3: =+'Portada '!$A$16 -> Ingeniero de Calidad / QE
A4: 2 | B4: ¿El alcance de laboratorio cubre las pruebas y mediciones descritas por el plan de control? / Are the tests and measurements according to the control plan, covered by laboratory scope? | C4: X | G4: =+'Portada '!$A$16 -> Ingeniero de Calidad / QE
A5: 3 | B5: ¿Los instrumentos se derivan del control plan y su fecha de calibración es vigente? / Are instruments derived from Control plan and its calibration date is not expired yet? | C5: X | G5: =+'Portada '!$A$16 -> Ingeniero de Calidad / QE
A6: 4 | B6: ¿El ingeniero de calidad está capacitado para llevar a cabo estudios de MSA? / Is QE trained to perform MSA studies? | C6: X | G6: =+'Portada '!$A$16 -> Ingeniero de Calidad / QE

Sheet 10
E1: NOTA: Cualquier N/A debe ser justificado en los comentarios NOTE: Any N/A found must be justified in the comments.
B2: Requisito / Requirement | C2: Si / Yes | D2: No | E2: N/A | F2: Comentarios/Acción requerida / Comments/Action required | G2: Responsable / Responsible | H2: Fecha / Date | I2: Solicitar los siguientes formatos a DCC / Request DCC the following formats | J2: F7360
A3: 1 | B3: ¿Son las características evaluadas derivadas del plan de control? / Are the evaluated characteristics derived from control plan? | C3: X | G3: =+'Portada '!$A$16 -> Ingeniero de Calidad / QE
A4: 2 | B4: ¿Son las características evaluadas derivadas de requerimientos del cliente? / Are the characteristics evaluated derived from cutomer requirements? | C4: X | G4: =+'Portada '!$A$16 -> Ingeniero de Calidad / QE
A5: 3 | B5: ¿Las características con inspección 100% se excluyen del SPC, a menos que el cliente especifique lo contrario? / Characteristics with 100% inspection are excluded from SPC. unless otherwise specified by customer? | C5: X | G5: =+'Portada '!$A$16 -> Ingeniero de Calidad / QE
A6: 4 | B6: ¿Se consideran los índices de Ppk/Cpk establecidos por los clientes? / Are the customer established Ppk/Cpk indexes considered ? | C6: X | G6: =+'Portada '!$A$16 -> Ingeniero de Calidad / QE
A7: 5 | B7: ¿El ingeniero de calidad está capacitado para llevar a cabo estudios de SPC? / Is QE trained to perform SPC studies? | C7: X | G7: =+'Portada '!$A$16 -> Ingeniero de Calidad / QE

Sheet 11
E1: NOTA: Cualquier N/A debe ser justificado en los comentarios NOTE: Any N/A found must be justified in the comments.
B2: Requisito / Requirement | C2: Si / Yes | D2: No | E2: N/A | F2: Comentarios/Acción requerida / Comments/Action required | G2: Responsable / Responsible | H2: Fecha / Date | I2: Solicitar los siguientes formatos a DCC / Request DCC the following formats | J2: F5620B F8510
A3: 1 | B3: ¿Se cuentan con registros de las reuniones periódicas del equipo multidisciplinario?/ Are follow up meetings records conducted by the CFT available? | C3: X | G3: =IF('Portada '!$A$14="","",'Portada '!$A$14) -> Líder del proyecto / Project leader
A4: 2 | B4: ¿El personal requerido para la operación de acuerdo al SWS, además de Staff ha sido solicitado? / The personnel required for the operation according to the SWS has been requested? | C4: X | G4: Gerente de operaciones / Operations Manager
A5: 3 | B5: ¿Se cuenta con el plan de reclutamiento disponible por parte de RH? / Is recruitment plan by HR available? | E5: X | G5: Gerente de Recursos Humanos / Human Resources Manager
A6: 4 | B6: ¿Se asegura que las características específicas del cliente son consideradas en los documentos aplicables para calidad? / Have customer specific characteristics been considered in applicable documents for quality? | C6: X | G6: Gerente de Calidad / Quality Manager
A7: 5 | B7: ¿El ingeniero de calidad está capacitado para llevar a cabo estudios de MSA y SPC? / Is QE trained to perform MSA and SPC studies? | C7: X | G7: Gerente de Calidad / Quality Manager
A8: 6 | B8: ¿Se cuentan con todas las QRs aplicables para nuevos componentes disponibles ? / Do applicable QRs exist for new components availability? | C8: X | G8: Gerente de SCS / SCS Manager
A9: 7 | B9: ¿Se cuenta con el archivo de RFQ tracker disponible? / Is RFQ tracker file available? | C9: X | G9: Gerente de SCS / SCS Manager
A10: 8 | B10: ¿Los TP de nuevos componentes están disponibles? / Are New components TP available? | C10: X | G10: Gerente de Finanzas / Finance Manager

Sheet 12
E1: NOTA: Cualquier N/A debe ser justificado en los comentarios NOTE: Any N/A found must be justified in the comments.
B2: Requisito / Requirement | C2: Si / Yes | D2: No | E2: N/A | F2: Comentarios/Acción requerida / Comments/Action required | G2: Responsable / Responsible | H2: Fecha / Date | I2: Solicitar los siguientes formatos a DCC / Request DCC the following formats | J2: F7360
A3: 1 | B3: ¿Durante la etapa 3 existieron "situaciones del cliente"? / During stage 2, did "customer situations" exist? | D3: X | G3: =+'Portada '!$A$16 -> Ingeniero de Calidad / QE
A4: 2 | B4: En caso afirmativo, ¿Se encuentra documentado? / If so, is it documented? | E4: X | G4: =+'Portada '!$A$16 -> Ingeniero de Calidad / QE
A5: 3 | B5: ¿El seguimiento del caso está actualizado? / Is case follow up updated? | E5: X | G5: =+'Portada '!$A$16 -> Ingeniero de Calidad / QE
C6: =IF(C3="X", ("1"), ("0")) -> 0
C7: =IF(C4="X", ("1"), ("0")) -> 0
C8: =IF(C5="X", ("1"), ("0")) -> 0
C9: =IF(#REF!="X", ("1"), ("0")) -> #REF!
C10: =IF(#REF!="X", ("1"), ("0")) -> #REF!
C11: =IF(#REF!="X", ("1"), ("0")) -> #REF!
C12: =IF(#REF!="X", ("1"), ("0")) -> #REF!
C13: =C6+C7+C8+C9+C10+C11+C12 -> #REF!

Sheet Stage 3
D2: Revisión de Etapa 3 / Stage 3 Review
B6: Cliente/Customer: | D6: =IF('Portada '!B7="", " ",+'Portada '!B7) -> Stellantis | E6: Fecha/Date:
B7: Nombre del proyecto/Project Name: | D7: =IF('Portada '!B5="", "",+'Portada '!B5) -> Dahlia Valve Stellantis | E7: Número de parte/Part Number: | F7: =+'Portada '!B6 -> 1722-EJB0033
B10: Si/Yes | C10: No | D10: Requerimiento/Requirement | E10: Comentarios/Comments
B11: X | D11: ¿Todos los puntos del APQP Checklist en la etapa revisada están cerrados? / Are all items of the APQP Checklist closed in the reviewed stage?
B12: X | D12: ¿Todos lo entregables de la etapa revisada fueron validados y auditados por el equipo de proyecto? / All deliverables of the reviewed stage were validated and audited by the project team?
B13: X | D13: ¿Los entregables fueron completados en tiempo de acuerdo a la línea de tiempo del cliente? / Were deliveries completed on time according to customer timeline?
B15: Fecha / Date | D15: Conclusión / Conclusion | E15: Comentarios /Comments
C16: Cierre/ Close | D16: El proyecto puede cerrarse.
C17: Desviación / Deviation | D17: Algunas situaciones menores quedarán abiertas y documentadas en el W3 de la línea
C18: Abierto/ Open | D18: La evidencia de cierre no es suficiente, la revisión necesita reprogramarse
B20: Stage 3 Responsibles
B21: Aprobaciones/Approvals: | D21: Position | E21: Name | F21: Email
D22: Project Engineer: | E22: Eduardo Tejeida | F22: eduardo.tejeida@johnsonelectric.com
D23: Quality Engineer: | E23: Gabriel Romero | F23: gabriel.romero@johnsonelectric.com
D24: Process Engineer: | E24: Jesus Urena | F24: jesus.urena@johnsonelectric.com
D25: Project Leader: | E25: Eduardo Tejeida | F25: eduardo.tejeida@johnsonelectric.com
B27: Manufacturing site Management
B28: Aprobaciones/Approvals: | D28: Position | E28: Name | F28: Email
D29: Operations Manager: | E29: Fermin Flores | F29: fermin.flores@johnsonelectric.com
D30: Quality Manager: | E30: Rodrigo Rabelo | F30: rodrigo.rabelo@johnsonelectric.com
D31: Materials Manager: | E31: Juan Carlos Arizpe | F31: Juancarlos.arizpe@johnsonelectric.com
D32: SCS Manager: | E32: Kevin Swisher | F32: kevin.swisher@jonsonelectric.com
D33: Finance Manager: | E33: Bernardo Marines | F33: Bernardo.marines@johnsonelectric.com
D34: HR Manager: | E34: Claudia Castañeda | F34: claudia.castaneda@johnsonelectric.com
F36: =+#REF! -> #REF!

Sheet 13
E1: NOTA: Cualquier N/A debe ser justificado en los comentarios NOTE: Any N/A found must be justified in the comments.
B2: Requisito / Requirement | C2: Si / Yes | D2: No | E2: N/A | F2: Comentarios/Acción requerida / Comments/Action required | G2: Responsable / Responsible | H2: Fecha / Date | I2: Solicitar los siguientes formatos a DCC / Request DCC the following formats | J2: F7360
A3: 1 | B3: ¿Es el material usado derivado de proveedores aprobados? / Is the material used from approved suppliers? | C3: X | G3: ICP / SQE
A4: 2 | B4: ¿Es el material usado el mismo que se usará para la producción normal?/Is the material used the same that will be used for normal production? | C4: X | G4: Procuramiento SCS / SCS Procurement
A5: 3 | B5: ¿Es el material suficiente para correr la producción especificada para pruebas? / Is enough material to run specific production for trials? | C5: X | G5: =+'[3]Portada '!$A$14 -> Líder del proyecto / Project leader
A6: 4 | B6: ¿La producción de muestras se hizo OT-OP?/ Was sample production made OT-OP? | C6: X | G6: =+'[3]Portada '!$A$17 -> Process Engineer / PE
A7: 5 | B7: ¿Los parámetros de las máquinas son conocidos y documentados? / Are the parameters of the machines known and documented? | C7: X | G7: =+'[3]Portada '!$A$17 -> Process Engineer / PE
A8: 6 | B8: ¿Las condiciones de iluminación son las adecuadas para el tipo de trabajo realizado? / ¿Are lighting conditions adequate for work type realized ? | C8: X | G8: =+'[3]Portada '!$A$17 -> Process Engineer / PE
A9: 7 | B9: ¿Está definido el rate de producción esperado? / Is the expected production rate defined? | C9: X | G9: =+'[3]Portada '!$A$14 -> Líder del proyecto / Project leader
A10: 8 | B10: ¿Está definido el takt time de la línea? / Is takt time line defined? | C10: X | G10: =+'[3]Portada '!$A$14 -> Líder del proyecto / Project leader
A11: 9 | B11: ¿El índice de scrap es definido debajo del permitido 0.35%? / Is scrap index defined to be lower than 0.35 %? | C11: X | G11: =+'[3]Portada '!$A$16 -> Ingeniero de Calidad / QE
A12: 10 | B12: ¿El tiempo muerto de la línea de producción es definido debajo del permitido 10%? / Is downtime metric defined in production line? | C12: X | G12: =+'[3]Portada '!$A$17 -> Process Engineer / PE

Sheet 14
E1: NOTA: Cualquier N/A debe ser justificado en los comentarios NOTE: Any N/A found must be justified in the comments.
B2: Requisito / Requirement | C2: Si / Yes | D2: No | E2: N/A | F2: Comentarios/Acción requerida / Comments/Action required | G2: Responsable / Responsible | H2: Fecha / Date | I2: Solicitar los siguientes formatos a DCC / Request DCC the following formats | J2: WCAL-110803 ANOVA F7600B L&S F7600F Atributos
A3: 1 | B3: ¿Las partes seleccionadas repesentan la variacion total del proceso? / Are these parts representative of the whole process variation? | C3: X | G3: =+'Portada '!$A$16 -> Ingeniero de Calidad / QE
A4: 2 | B4: ¿Se lleva a cabo el proceso de medición de acuerdo a R&R? / Is the R&R process followed up? | C4: X | G4: =+'Portada '!$A$16 -> Ingeniero de Calidad / QE
A5: 3 | B5: ¿El NDC del estudio es => a 5? / Is the NDC => to 5? | C5: X | G5: =+'Portada '!$A$16 -> Ingeniero de Calidad / QE
A6: 4 | B6: ¿La gráfica X-R por operador muestra más del 50% de los puntos por encima de los límites de punto ciego? / Are the points in the X-R chart out of the blind point over 50%? | C6: X | G6: =+'Portada '!$A$16 -> Ingeniero de Calidad / QE
A7: 5 | B7: ¿La gráfica R por operador muestras todos los puntos dentro de los límites de control? / Are all the points in the operator's R chart within the control limits? | C7: X | G7: =+'Portada '!$A$16 -> Ingeniero de Calidad / QE
A8: 6 | B8: ¿Los cambios en la gráfica R indican una buena resolución del instrumento? / Are the changes in the R chart an indication of a proper instrument resolution? | C8: X | G8: =+'Portada '!$A$16 -> Ingeniero de Calidad / QE
A9: 7 | B9: En la gráfica operador contra muestra no se denotan interacciones grandes entre el usuario y la pieza? / In the appraiser vs part chart, is it shown a big interaction between them? | C9: X | G9: =+'Portada '!$A$16 -> Ingeniero de Calidad / QE
A10: 8 | B10: La gráfica de mediciones entre operadores no muestra variaciones importantes? / Does the measurements between appraisers chart show significant variation? | C10: X | G10: =+'Portada '!$A$16 -> Ingeniero de Calidad / QE
A11: 9 | B11: ¿El porcentaje de variación del estudio está por debajo del 10%? / Is the study variation percentage below 10%? | C11: X | G11: =+'Portada '!$A$16 -> Ingeniero de Calidad / QE

Sheet 15
E1: NOTA: Cualquier N/A debe ser justificado en los comentarios NOTE: Any N/A found must be justified in the comments.
B2: Requisito / Requirement | C2: Si / Yes | D2: No | E2: N/A | F2: Comentarios/Acción requerida / Comments/Action required | G2: Responsable / Responsible | H2: Fecha / Date | I2: Solicitar los siguientes formatos a DCC / Request DCC the following formats | J2: F8231 Pre-SPC
A3: 1 | B3: ¿Atienden los índices de Pp, Cp, Ppk y Cpk los requerimientos de los clientes? / Are Pp, Cp, Ppk an Cpk indexes according to customer requirements? | C3: X | G3: =+'Portada '!$A$16 -> Ingeniero de Calidad / QE
A4: 2 | B4: ¿El equipo utilizado para llevar a cabo las mediciones tiene registros de estudios de MSA, calibración y/o verificación? / Does the equipment used to carry out the measurements have MSA study records, calibration and/or verification? | C4: X | G4: =+'Portada '!$A$16 -> Ingeniero de Calidad / QE
A5: 3 | B5: ¿El número de muestras para características de desempeño es de mínimo 100? / Is the number of samples taken for performance characteristics at least of 100? | C5: X | G5: =+'Portada '!$A$16 -> Ingeniero de Calidad / QE
A6: 4 | B6: ¿Son las muestras tomadas de una corrida significativa? / Are the samples taken from a significant run? | C6: X | G6: =+'Portada '!$A$16 -> Ingeniero de Calidad / QE
A7: 5 | B7: ¿Para los procesos que no cumplan con el índice de Ppk, ¿se identifican las causas y hay acciones de mejora? / For processes which Ppk index is non compliant, have causes and actions been identified? | E7: X | G7: =+'Portada '!$A$16 -> Ingeniero de Calidad / QE
A8: 6 | B8: ¿Existe un plan de acción para las características no conformes? / Does an action plan exist for non-conforming characteristics? | C8: X | F8: Action plan para rechazo de actuador | G8: =+'Portada '!$A$16 -> Ingeniero de Calidad / QE | H8: 45566
A9: 7 | B9: En base a los resultados, ¿se definen las características que serán monitoreadas durante la producción regular? / Based on results, are characteristics that will be monitored during regular production defined? | C9: X | G9: =+'Portada '!$A$16 -> Ingeniero de Calidad / QE

Sheet 16
E1: NOTA: Cualquier N/A debe ser justificado en los comentarios NOTE: Any N/A found must be justified in the comments.
B2: Requisito / Requirement | C2: Si / Yes | D2: No | E2: N/A | F2: Comentarios/Acción requerida / Comments/Action required | G2: Responsable / Responsible | H2: Fecha / Date
A3: 1 | B3: ¿Se conoce el nivel de PPAP solicitado por el cliente? / Is PPAP level requested by customer known ? | C3: X | G3: =+'Portada '!$A$16 -> Ingeniero de Calidad / QE
A4: 2 | B4: Registros de diseño / Design Record | C4: X | G4: =+'Portada '!$A$16 -> Ingeniero de Calidad / QE
A5: 3 | B5: Documentos de cambios de ingeniería / Engineering Change Documents | C5: X | G5: =+'Portada '!$A$16 -> Ingeniero de Calidad / QE
A6: 4 | B6: FMEA de diseño / Design FMEA | C6: X | G6: =+'Portada '!$A$16 -> Ingeniero de Calidad / QE
A7: 5 | B7: Diagrama del flujo de proceso / Process Flow Diagram | C7: X | G7: =+'Portada '!$A$16 -> Ingeniero de Calidad / QE
A8: 6 | B8: FMEA de procesos / Process FMEA | C8: X | G8: =+'Portada '!$A$16 -> Ingeniero de Calidad / QE
A9: 7 | B9: Plan de control / Control Plan | C9: X | G9: =+'Portada '!$A$16 -> Ingeniero de Calidad / QE
A10: 8 | B10: Estudios de MSA / MSA Studies | C10: X | G10: =+'Portada '!$A$16 -> Ingeniero de Calidad / QE
A11: 9 | B11: Resultados dimensionales / Dimensional Results | C11: X | G11: =+'Portada '!$A$16 -> Ingeniero de Calidad / QE
A12: 10 | B12: Resultados de pruebas de material y desempeño / Material & Performance test result | C12: X | G12: =+'Portada '!$A$16 -> Ingeniero de Calidad / QE
A13: 11 | B13: Estudio inicial de proceso / Initial Process Study | C13: X | G13: =+'Portada '!$A$16 -> Ingeniero de Calidad / QE
A14: 12 | B14: Documentación del laboratorio / Qualified Laboratory Documentation | C14: X | G14: =+'Portada '!$A$16 -> Ingeniero de Calidad / QE
A15: 13 | B15: Reporte de aprobación de apariencia / Appearance Approval Report | E15: X | G15: =+'Portada '!$A$16 -> Ingeniero de Calidad / QE
A16: 14 | B16: Partes de muestra de producción / Sample Production Parts | C16: X | G16: =+'Portada '!$A$16 -> Ingeniero de Calidad / QE
A17: 15 | B17: Muestra maestra / Master Sample | C17: X | G17: =+'Portada '!$A$16 -> Ingeniero de Calidad / QE
A18: 16 | B18: Ayudas visuales / Checking Aids | C18: X | G18: =+'Portada '!$A$16 -> Ingeniero de Calidad / QE
A19: 17 | B19: Registros de cumplimiento / Records of Compliance | C19: X | G19: =+'Portada '!$A$16 -> Ingeniero de Calidad / QE
A20: 18 | B20: Garantía del envío de piezas / Part Submission Warrant | C20: X | G20: =+'Portada '!$A$16 -> Ingeniero de Calidad / QE
A21: 19 | B21: Datos de IMDS / IMDS Data | C21: X | G21: =+'Portada '!$A$16 -> Ingeniero de Calidad / QE

Sheet 17
E1: NOTA: Cualquier N/A debe ser justificado en los comentarios NOTE: Any N/A found must be justified in the comments.
B2: Requisito / Requirement | C2: Si / Yes | D2: No | E2: N/A | F2: Comentarios/Acción requerida / Comments/Action required | G2: Responsable / Responsible | H2: Fecha / Date
A3: 1 | B3: ¿Se tiene un plan de pruebas de PV desarrollado por ingeniería? / Is a PV test plan developed by engineering? | C3: X | G3: Equipo de calidad para lanzamientos
A4: 2 | B4: ¿La evaluación del dimensional de las partes está disponible? / Is parts dimensional test available? | C4: X | G4: Equipo de calidad para lanzamientos
A5: 3 | B5: ¿La evaluación del desempeño de las partes está disponible? / Is parts performance test available? | C5: X | G5: Equipo de calidad para lanzamientos
A6: 4 | B6: ¿Los resultados del PV test son satisfactorios? / Are PV test results satisfactory? | C6: X | G6: Equipo de calidad para lanzamientos

Sheet 18
E1: NOTA: Cualquier N/A debe ser justificado en los comentarios NOTE: Any N/A found must be justified in the comments.
